package com.gtocore.common.machine.multiblock.electric;

import com.gtocore.api.data.tag.GTOTagPrefix;
import com.gtocore.api.pattern.GTOPredicates;
import com.gtocore.api.pattern.StructureModuleKeys;
import com.gtocore.common.data.GTOBlocks;
import com.gtocore.common.data.GTOMaterials;

import com.gtolib.api.annotation.DataGeneratorScanned;
import com.gtolib.api.annotation.language.RegisterLanguage;
import com.gtolib.api.machine.feature.multiblock.IStorageMultiblock;
import com.gtolib.api.machine.multiblock.StorageMultiblockMachine;
import com.gtolib.api.recipe.GTORecipeModifiers;
import com.gtolib.api.recipe.IdleReason;

import com.gregtechceu.gtceu.api.blockentity.MetaMachineBlockEntity;
import com.gregtechceu.gtceu.api.data.chemical.ChemicalHelper;
import com.gregtechceu.gtceu.api.data.chemical.material.Material;
import com.gregtechceu.gtceu.api.data.chemical.material.stack.MaterialStack;
import com.gregtechceu.gtceu.api.machine.MultiblockMachineDefinition;
import com.gregtechceu.gtceu.api.machine.multiblockpro.ParamKey;
import com.gregtechceu.gtceu.api.machine.multiblockpro.Piece;
import com.gregtechceu.gtceu.api.machine.multiblockpro.Slot;
import com.gregtechceu.gtceu.api.machine.multiblockpro.Structure;
import com.gregtechceu.gtceu.api.machine.multiblockpro.Symbols;
import com.gregtechceu.gtceu.api.pattern.util.RelativeDirection;
import com.gregtechceu.gtceu.api.recipe.GTRecipe;
import com.gregtechceu.gtceu.api.recipe.handler.RecipeHandlerUnit;
import com.gregtechceu.gtceu.common.data.GTBlocks;
import com.gregtechceu.gtceu.common.data.GTMaterials;
import com.gregtechceu.gtceu.uiwidgets.multiblock.MultiblockPage;

import net.minecraft.MethodsReturnNonnullByDefault;
import net.minecraft.network.chat.Component;

import com.gto.datasynclib.annotations.SaveToDisk;
import com.gto.datasynclib.annotations.SyncToClient;
import org.jetbrains.annotations.Nullable;

import java.util.List;

import javax.annotation.ParametersAreNonnullByDefault;

import static com.gregtechceu.gtceu.api.machine.multiblock.PartAbility.MAINTENANCE;
import static com.gregtechceu.gtceu.api.machine.multiblock.PartAbility.PARALLEL_HATCH;
import static com.gregtechceu.gtceu.api.pattern.Predicates.*;

@DataGeneratorScanned
@ParametersAreNonnullByDefault
@MethodsReturnNonnullByDefault
public final class PCBFactoryMachine extends StorageMultiblockMachine {

    @RegisterLanguage(en = "PCB Factory Tier: ", cn = "PCB工厂等级：")
    public static final String TIER = "gtocore.pcb_factory.tier";

    @RegisterLanguage(cn = "结构等级：%s", en = "Structure Tier: %s")
    private static final String STRUCTURE_TIER = "gtocore.pcb_factory.structure_tier";
    @RegisterLanguage(cn = "纳米蜂群等级：%s", en = "Nanoswarm Tier: %s")
    private static final String SWARM_TIER = "gtocore.pcb_factory.swarm_tier";
    @RegisterLanguage(cn = "生效等级：%s（取结构等级与纳米蜂群等级中的较低者）", en = "Effective Tier: %s (lower of structure tier and nanoswarm tier)")
    private static final String EFFECTIVE_TIER = "gtocore.pcb_factory.effective_tier";
    @RegisterLanguage(cn = "生效等级", en = "Effective Tier")
    private static final String EFFECTIVE_TIER_NAME = "gtocore.machine.pcb_factory.effective_tier";
    @RegisterLanguage(cn = "取结构等级与纳米蜂群等级中的较低者", en = "The lower of the structure tier and the nanoswarm tier")
    private static final String EFFECTIVE_TIER_DESC = "gtocore.machine.pcb_factory.effective_tier.desc";

    @RegisterLanguage(cn = "二级扩展结构", en = "Tier 2 Extension")
    private static final String TIER2_NAME = "gtocore.multiblock.pcb_factory.tier2";
    @RegisterLanguage(cn = "搭建后结构等级提升至 2，可在其后方继续搭建三级扩展结构", en = "Raises the structure tier to 2; the tier 3 extension attaches behind it")
    private static final String TIER2_DESC = "gtocore.multiblock.pcb_factory.tier2.desc";
    @RegisterLanguage(cn = "三级扩展结构", en = "Tier 3 Extension")
    private static final String TIER3_NAME = "gtocore.multiblock.pcb_factory.tier3";
    @RegisterLanguage(cn = "搭建后结构等级提升至 3", en = "Raises the structure tier to 3")
    private static final String TIER3_DESC = "gtocore.multiblock.pcb_factory.tier3.desc";

    public static final ParamKey TIER2_MODULE = ParamKey.of(TIER2_NAME, TIER2_DESC);
    public static final ParamKey TIER3_MODULE = ParamKey.of(TIER3_NAME, TIER3_DESC);

    @SaveToDisk(defaultValue = "1")
    @SyncToClient
    private int machineTier = 1;

    @SyncToClient
    private int structureTier = 1;

    public PCBFactoryMachine(MetaMachineBlockEntity holder) {
        super(holder, 1, i -> ChemicalHelper.getPrefix(i.getItem()) == GTOTagPrefix.NANITES);
    }

    @Override
    public void onMachineChanged() {
        machineTier = 0;
        MaterialStack stack = ChemicalHelper.getMaterialStack(getStorageStack());
        if (stack.isEmpty()) return;
        Material material = stack.material();
        if (material == GTMaterials.Gold) {
            machineTier = 1;
        } else if (material == GTOMaterials.Orichalcum) {
            machineTier = 2;
        } else if (material == GTOMaterials.Enderium) {
            machineTier = 3;
        }
    }

    @Override
    public void onStructureFormed() {
        super.onStructureFormed();
        var assembly = getAssembly();
        structureTier = assembly == null ? 1 : 1 + (assembly.has(TIER2_MODULE) ? 1 : 0) + (assembly.has(TIER3_MODULE) ? 1 : 0);
    }

    @Override
    public void onStructureInvalid() {
        super.onStructureInvalid();
        structureTier = 1;
    }

    public int getEffectiveTier() {
        return Math.min(Math.max(machineTier, 1), structureTier);
    }

    public static Structure structure(MultiblockMachineDefinition definition) {
        return Structure.root(mainPiece())
                .symbols(Symbols.create()
                        .where('@', any())
                        .where('$', any())
                        .where('A', blocks(GTOBlocks.BORON_CARBIDE_CERAMIC_RADIATION_RESISTANT_MECHANICAL_CUBE.get()))
                        .where('B', GTOPredicates.frame(GTMaterials.MaragingSteel300))
                        .where('C', blocks(GTBlocks.CASING_TEMPERED_GLASS.get()))
                        .where('D', blocks(GTOBlocks.PRESSURE_CONTAINMENT_CASING.get()))
                        .wherePart('E', blocks(GTOBlocks.IRIDIUM_CASING.get())
                                .or(GTOPredicates.autoLaserAbilities(definition.getRecipeTypes()))
                                .or(abilities(PARALLEL_HATCH).setMaxGlobalLimited(1))
                                .or(abilities(MAINTENANCE).setExactLimit(1)))
                        .where('F', blocks(GTOBlocks.MAGTECH_CASING.get()))
                        .where('G', blocks(GTOBlocks.STRONTIUM_CARBONATE_CERAMIC_RAY_ABSORBING_MECHANICAL_CUBE.get()))
                        .where('H', GTOPredicates.frame(GTMaterials.Europium))
                        .where('I', blocks(GTOBlocks.PPS_CORROSION_RESISTANT_MECHANICAL_HOUSING.get()))
                        .where('J', blocks(GTBlocks.HERMETIC_CASING_ZPM.get()))
                        .where('K', controller(definition))
                        .where('L', blocks(GTOBlocks.NAQUADAH_ALLOY_CASING.get()))
                        .where('M', blocks(GTOBlocks.IRIDIUM_CASING.get()))
                        .where('N', blocks(GTBlocks.HIGH_POWER_CASING.get()))
                        .where('O', GTOPredicates.frame(GTMaterials.Neutronium))
                        .where('P', blocks(GTOBlocks.GRAVITY_STABILIZATION_CASING.get()))
                        .where('Q', blocks(GTOBlocks.RADIATION_ABSORBENT_CASING.get()))
                        .where('R', blocks(GTOBlocks.ADVANCED_ASSEMBLY_LINE_UNIT.get()))
                        .where('S', blocks(GTBlocks.SUPERCONDUCTING_COIL.get()))
                        .where('T', blocks(GTOBlocks.HOLLOW_CASING.get()))
                        .where('U', blocks(GTOBlocks.PLASMA_HEATER_CASING.get()))
                        .where('V', blocks(GTOBlocks.MOLECULAR_COIL.get()))
                        .where('W', blocks(GTOBlocks.AMPROSIUM_ACTIVE_CASING.get()))
                        .where('X', blocks(GTOBlocks.CONTAINMENT_FIELD_GENERATOR.get()))
                        .where('Y', blocks(GTOBlocks.HIGH_ENERGY_ULTRAVIOLET_EMITTER_CASING.get())))
                .atPort(StructureModuleKeys.MODULE_OUT, Slot.optional(tier2Piece(), StructureModuleKeys.MODULE_IN).count(TIER2_MODULE)
                        .atPort(StructureModuleKeys.MODULE_OUT, Slot.optional(tier3Piece(), StructureModuleKeys.MODULE_IN).count(TIER3_MODULE)))
                .build();
    }

    private static Piece mainPiece() {
        return Piece.start(RelativeDirection.LEFT, RelativeDirection.UP, RelativeDirection.FRONT)
                .aisle("    AAAAA    ", "             ", "             ", "      $      ", "             ", "             ", "             ", "             ", "             ", "             ", "             ", "             ", "             ", "             ", "    BBBBB    ", "      B      ")
                .aisle("   AAAAAAA   ", "    CCACC    ", "    CCACC    ", "    CCACC    ", "    CCACC    ", "    CCACC    ", "    CCACC    ", "    CCACC    ", "    CCACC    ", "    CCACC    ", "    CCACC    ", "    CCACC    ", "    CCACC    ", "    CCACC    ", "   BAAAAAB   ", "      B      ")
                .aisle("  AAAAAAAAA  ", "   C     C   ", "   C     C   ", "   C     C   ", "   C     C   ", "   C     C   ", "   C B B C   ", "   C  B  C   ", "   C B B C   ", "   C     C   ", "   C     C   ", "   C     C   ", "   C     C   ", "   C     C   ", "  BAAAAAAAB  ", "      B      ")
                .aisle(" AAAAAAAAAAA ", "  C  DDD  C  ", "  C  DDD  C  ", "  C  DDD  C  ", "  C  DDD  C  ", "  C BDDDB C  ", "  C  DDD  C  ", "  C  DDD  C  ", "  C  DDD  C  ", "  C BDDDB C  ", "  C  DDD  C  ", "  C  DDD  C  ", "  C  DDD  C  ", "  C  DDD  C  ", " BAAAAAAAAAB ", "     DDD     ")
                .aisle("AAAAAAAAAAAAA", " C  D   D  C ", " C  D   D  C ", " C  D   D  C ", " C BD   DB C ", " C  D   D  C ", " C  D   D  C ", " C  D   D  C ", " C  D   D  C ", " C  D   D  C ", " C BD   DB C ", " C  D   D  C ", " C  D   D  C ", " C  D   D  C ", "BAAAAAAAAAAAB", "    DDDDD    ")
                .aisle("AAAAAAAAAAAAA", " C DF J FD C ", " C DH J HD C ", " CBDF J FDBC ", " C DH J HD C ", " C DF J FD C ", " C DH J HD C ", " C DF J FD C ", " C DH J HD C ", " C DF J FD C ", " C DH J HD C ", " CBDF J FDBC ", " C DH J HD C ", " C DF J FD C ", "BAAAAAAAAAAAB", "BBBBDDDDDBBBB")
                .aisle("AAAAAAAAAAAAA", " C  D   D  C ", " C BD   DB C ", " C  D J D  C ", " C  D   D  C ", " C  D   D  C ", " C  D   D  C ", " C  D J D  C ", " C  D   D  C ", " C  D   D  C ", " C  D   D  C ", " C  D J D  C ", " C BD   DB C ", " C  D   D  C ", "BAAAAAAAAAAAB", "    DDDDD    ")
                .aisle("AAAAAAAAAAAAA", " BAADIIIDAAB ", " BAADDDDDAAB ", " BAADDJDDAAB ", " BAADDDDDAAB ", " BAADIIIDAAB ", " BAADDDDDAAB ", " BAADDJDDAAB ", " BAADDDDDAAB ", " BAADIIIDAAB ", " BAADDDDDAAB ", " BAADDJDDAAB ", " BAADDDDDAAB ", " BAADIIIDAAB ", " BAAAAAAAAAB ", "     DDD     ")
                .aisle(" AAAAAAAAAAA ", "  BEGAHAGEB  ", "  BEGAHAGEB  ", "  BEGAJAGEB  ", "  BEGAHAGEB  ", "  BEGAHAGEB  ", "  B GAHAG B  ", "  B GAJAG B  ", "  B GAHAG B  ", "  B GAHAG B  ", "  B GAHAG B  ", "  B GAJAG B  ", "  B GAHAG B  ", "  B GAHAG B  ", "  BAAAAAAAB  ", "      B      ")
                .aisle("  AAAAAAAAA  ", "   EHAAAHE   ", "   EHAAAHE   ", "   EHAJAHE   ", "   EHAAAHE   ", "   EEAAAEE   ", "     AAA     ", "     ADA     ", "     AAA     ", "     AAA     ", "     AAA     ", "     ADA     ", "     AAA     ", "     AAA     ", "   BAAAAAB   ", "      B      ")
                .aisle("  AAAAAAAAA  ", "   EEEJEEE   ", "   EEEJEEE   ", "   EEEJEEE   ", "   EEEEEEE   ", "   EEEEEEE   ", "             ", "      D      ", "             ", "             ", "             ", "      D      ", "             ", "             ", "    BBBBB    ", "      B      ")
                .aisle("   AAAAAAA   ", "    GEJEG    ", "    GEJEG    ", "    GEJEG    ", "     EDE     ", "      D      ", "      D      ", "      D      ", "      D      ", "      D      ", "      D      ", "      D      ", "             ", "             ", "             ", "             ")
                .aisle("    AAAAA    ", "     EEE     ", "     EEE     ", "     EKE     ", "     EEE     ", "             ", "             ", "             ", "             ", "             ", "             ", "             ", "             ", "             ", "             ", "             ")
                .aisle("     AAA     ", "             ", "             ", "             ", "             ", "             ", "             ", "             ", "             ", "             ", "             ", "             ", "             ", "             ", "             ", "             ")
                .port('$', StructureModuleKeys.MODULE_OUT, RelativeDirection.BACK)
                .build();
    }

    private static Piece tier2Piece() {
        return Piece.start(RelativeDirection.LEFT, RelativeDirection.UP, RelativeDirection.FRONT)
                .aisle("       LLLLL       ", "        LLL        ", "         L         ", "         $         ", "                   ", "                   ", "                   ", "                   ", "                   ", "                   ", "                   ", "                   ", "                   ", "                   ", "                   ", "                   ", "                   ", "                   ", "                   ", "                   ", "                   ", "                   ", "                   ", "                   ", "                   ", "                   ", "                   ", "                   ", "                   ", "                   ")
                .aisle("       LMNML       ", "       LLOLL       ", "        LLL        ", "                   ", "                   ", "                   ", "                   ", "                   ", "                   ", "                   ", "                   ", "                   ", "                   ", "                   ", "                   ", "                   ", "                   ", "                   ", "                   ", "                   ", "                   ", "                   ", "                   ", "                   ", "                   ", "                   ", "                   ", "                   ", "                   ", "                   ")
                .aisle("     LLOMNMOLL     ", "       LOOOL       ", "        LLL        ", "                   ", "                   ", "                   ", "                   ", "                   ", "                   ", "                   ", "                   ", "                   ", "                   ", "                   ", "                   ", "                   ", "                   ", "                   ", "                   ", "                   ", "                   ", "                   ", "                   ", "                   ", "                   ", "                   ", "                   ", "                   ", "                   ", "                   ")
                .aisle("    L  MMNMM  L    ", "                   ", "                   ", "                   ", "                   ", "                   ", "                   ", "                   ", "                   ", "                   ", "                   ", "                   ", "                   ", "                   ", "                   ", "                   ", "                   ", "                   ", "                   ", "                   ", "                   ", "                   ", "                   ", "                   ", "                   ", "                   ", "                   ", "                   ", "                   ", "                   ")
                .aisle("   L MMMMNMMMM L   ", "        LNL        ", "       LLNLL       ", "       LLNLL       ", "        L L        ", "        L L        ", "        L L        ", "        L L        ", "        L L        ", "                   ", "                   ", "                   ", "                   ", "                   ", "                   ", "                   ", "                   ", "                   ", "                   ", "                   ", "                   ", "                   ", "                   ", "                   ", "                   ", "                   ", "                   ", "                   ", "                   ", "                   ")
                .aisle("  L MMMMMMMMMMM L  ", "       GPQPG       ", "      LPPQPPL      ", "      LLLNLLL      ", "       LLNLL       ", "        LNL        ", "       OLNLO       ", "        LNL        ", "        LNL        ", "        L L        ", "       OL LO       ", "        L L        ", "        L L        ", "        L L        ", "       OL LO       ", "        L L        ", "        L L        ", "        L L        ", "        L L        ", "        L L        ", "                   ", "                   ", "                   ", "                   ", "                   ", "                   ", "                   ", "                   ", "                   ", "                   ")
                .aisle("  L MMMMMMMMMMM L  ", "      GRRRRRG      ", "     LPRRRRRPL     ", "     LPPPQPPPL     ", "      PPPQPPP      ", "      PPPQPPP      ", "      OPPQPPO      ", "       PPQPP       ", "       PPNPP       ", "       PPNPP       ", "      OPPNPPO      ", "       PPNPP       ", "       PPNPP       ", "       PPNPP       ", "      OPPNPPO      ", "       PPNPP       ", "       PPNPP       ", "       PPNPP       ", "       OLNLO       ", "        LNL        ", "        L L        ", "        L L        ", "        L L        ", "        L L        ", "        L L        ", "                   ", "                   ", "                   ", "                   ", "                   ")
                .aisle("LLOMMMMMMMMMMMMMOLL", " LL  GROSSSORG  LL ", "    LPRO   ORPL    ", "    LLPOSSSOPLL    ", "     LPO   OPL     ", "      POSSSOP      ", "     OPO   OPO     ", "      POSSSOP      ", "      PO   OP      ", "      POSSSOP      ", "     OPO   OPO     ", "      POSSSOP      ", "      PO   OP      ", "      POSSSOP      ", "     OPO   OPO     ", "      POSSSOP      ", "      PO   OP      ", "      POSSSOP      ", "      OPP PPO      ", "       PPNPP       ", "       PPNPP       ", "        PNP        ", "        PNP        ", "        PNP        ", "       LLNLL       ", "         N         ", "         N         ", "         N         ", "         N         ", "         N         ")
                .aisle("LMMMMMMMMMMMMMMMMML", "LLO LPRS   SRPL OLL", " LL LPR     RPL LL ", "    LLPS   SPLL    ", "    LLP     PLL    ", "    LLPS   SPLL    ", "    LLP     PLL    ", "    LLPS   SPLL    ", "    LLP     PLL    ", "     LPS   SPL     ", "     LP     PL     ", "     LPS   SPL     ", "     LP     PL     ", "     LPS   SPL     ", "     LP     PL     ", "     LPS   SPL     ", "     LP     PL     ", "     LPS   SPL     ", "     LLP   PLL     ", "     LLP   PLL     ", "      LP   PL      ", "      LP   PL      ", "      LP   PL      ", "      LP   PL      ", "      LL   LL      ", "                   ", "                   ", "                   ", "                   ", "                   ")
                .aisle("LNNNNMMMMMMMMMNNNNL", "LOO NQRS T SRQN OOL", "LLL NQR  T  RQN LLL", "    NNQS T SQNN    ", "     NQ  T  QN     ", "     NQS T SQN     ", "     NQ  T  QN     ", "     NQS T SQN     ", "     NN  T  NN     ", "      NS T SN      ", "      N  T  N      ", "      NS T SN      ", "      N  T  N      ", "      NS T SN      ", "      N  T  N      ", "      NS T SN      ", "      N  T  N      ", "      NS T SN      ", "      N  T  N      ", "      NN T NN      ", "       N   N       ", "       N   N       ", "       N   N       ", "       N   N       ", "       N   N       ", "       N   N       ", "       N   N       ", "       N   N       ", "       N   N       ", "       N   N       ")
                .aisle("LMMMMMMMMMMMMMMMMML", "LLO LPRS   SRPL OLL", " LL LPR     RPL LL ", "    LLPS   SPLL    ", "    LLP     PLL    ", "    LLPS   SPLL    ", "    LLP     PLL    ", "    LLPS   SPLL    ", "    LLP     PLL    ", "     LPS   SPL     ", "     LP     PL     ", "     LPS   SPL     ", "     LP     PL     ", "     LPS   SPL     ", "     LP     PL     ", "     LPS   SPL     ", "     LP     PL     ", "     LPS   SPL     ", "     LLP   PLL     ", "     LLP   PLL     ", "      LP   PL      ", "      LP   PL      ", "      LP   PL      ", "      LP   PL      ", "      LL   LL      ", "                   ", "                   ", "                   ", "                   ", "                   ")
                .aisle("LLOMMMMMMMMMMMMMOLL", " LL  GROSSSORG  LL ", "    LPRO   ORPL    ", "    LLPOSSSOPLL    ", "     LPO   OPL     ", "      POSSSOP      ", "     OPO   OPO     ", "      POSSSOP      ", "      PO   OP      ", "      POSSSOP      ", "     OPO   OPO     ", "      POSSSOP      ", "      PO   OP      ", "      POSSSOP      ", "     OPO   OPO     ", "      POSSSOP      ", "      PO   OP      ", "      POSSSOP      ", "      OPP PPO      ", "       PPNPP       ", "       PPNPP       ", "        PNP        ", "        PNP        ", "        PNP        ", "       LLNLL       ", "         N         ", "         N         ", "         N         ", "         N         ", "         N         ")
                .aisle("  L MMMMMMMMMMM L  ", "      GRRRRRG      ", "     LPRRRRRPL     ", "     LPPPQPPPL     ", "      PPPQPPP      ", "      PPPQPPP      ", "      OPPQPPO      ", "       PPQPP       ", "       PPNPP       ", "       PPNPP       ", "      OPPNPPO      ", "       PPNPP       ", "       PPNPP       ", "       PPNPP       ", "      OPPNPPO      ", "       PPNPP       ", "       PPNPP       ", "       PPNPP       ", "       OLNLO       ", "        LNL        ", "        L L        ", "        L L        ", "        L L        ", "        L L        ", "        L L        ", "                   ", "                   ", "                   ", "                   ", "                   ")
                .aisle("  L MMMMMMMMMMM L  ", "       GPQPG       ", "      LPPQPPL      ", "      LLLNLLL      ", "       LLNLL       ", "        LNL        ", "       OLNLO       ", "        LNL        ", "        LNL        ", "        L L        ", "       OL LO       ", "        L L        ", "        L L        ", "        L L        ", "       OL LO       ", "        L L        ", "        L L        ", "        L L        ", "        L L        ", "        L L        ", "                   ", "                   ", "                   ", "                   ", "                   ", "                   ", "                   ", "                   ", "                   ", "                   ")
                .aisle("   L MMMMNMMMM L   ", "        LNL        ", "       LLNLL       ", "       LLNLL       ", "        L L        ", "        L L        ", "        L L        ", "        L L        ", "        L L        ", "                   ", "                   ", "                   ", "                   ", "                   ", "                   ", "                   ", "                   ", "                   ", "                   ", "                   ", "                   ", "                   ", "                   ", "                   ", "                   ", "                   ", "                   ", "                   ", "                   ", "                   ")
                .aisle("    L  MMNMM  L    ", "                   ", "                   ", "                   ", "                   ", "                   ", "                   ", "                   ", "                   ", "                   ", "                   ", "                   ", "                   ", "                   ", "                   ", "                   ", "                   ", "                   ", "                   ", "                   ", "                   ", "                   ", "                   ", "                   ", "                   ", "                   ", "                   ", "                   ", "                   ", "                   ")
                .aisle("     LLOMNMOLL     ", "       LOOOL       ", "        LLL        ", "                   ", "                   ", "                   ", "                   ", "                   ", "                   ", "                   ", "                   ", "                   ", "                   ", "                   ", "                   ", "                   ", "                   ", "                   ", "                   ", "                   ", "                   ", "                   ", "                   ", "                   ", "                   ", "                   ", "                   ", "                   ", "                   ", "                   ")
                .aisle("       LMNML       ", "       LLOLL       ", "        LLL        ", "                   ", "                   ", "                   ", "                   ", "                   ", "                   ", "                   ", "                   ", "                   ", "                   ", "                   ", "                   ", "                   ", "                   ", "                   ", "                   ", "                   ", "                   ", "                   ", "                   ", "                   ", "                   ", "                   ", "                   ", "                   ", "                   ", "                   ")
                .aisle("       LLLLL       ", "        LLL        ", "         L         ", "                   ", "                   ", "                   ", "                   ", "                   ", "                   ", "                   ", "                   ", "                   ", "                   ", "                   ", "                   ", "                   ", "                   ", "                   ", "                   ", "                   ", "                   ", "                   ", "                   ", "                   ", "                   ", "                   ", "                   ", "                   ", "                   ", "                   ")
                .aisle("                   ", "                   ", "                   ", "         @         ", "                   ", "                   ", "                   ", "                   ", "                   ", "                   ", "                   ", "                   ", "                   ", "                   ", "                   ", "                   ", "                   ", "                   ", "                   ", "                   ", "                   ", "                   ", "                   ", "                   ", "                   ", "                   ", "                   ", "                   ", "                   ", "                   ")
                .port('@', StructureModuleKeys.MODULE_IN, RelativeDirection.FRONT)
                .port('$', StructureModuleKeys.MODULE_OUT, RelativeDirection.BACK)
                .build();
    }

    private static Piece tier3Piece() {
        return Piece.start(RelativeDirection.LEFT, RelativeDirection.UP, RelativeDirection.FRONT)
                .aisle("               LLLLLLLLLLLLLLLLL               ", "                   L   L   L                   ", "                   L   L   L                   ", "               MMMMMMMMMMMMMMMMM               ", "                                               ", "                                               ", "                                               ", "                                               ", "                                               ", "                                               ", "                                               ", "                                               ", "                                               ", "                                               ", "                                               ", "                                               ", "                                               ", "                                               ", "                                               ", "                                               ")
                .aisle("              LLQQQQQQQQQQQQQQQLL              ", "                ALLLLLLLLLLLLLA                ", "                ACCCCCCCCCCCCCA                ", "               MALLLLLLLLLLLLLAM               ", "                   O   O   O                   ", "                   O   O   O                   ", "                   O   O   O                   ", "                   O   O   O                   ", "                   O   O   O                   ", "                   O   O   O                   ", "                                               ", "                                               ", "                                               ", "                                               ", "                                               ", "                                               ", "                                               ", "                                               ", "                                               ", "                                               ")
                .aisle("              LQQQQQQQQQQQQQQQQQL              ", "               MANOONOONOONOONAM               ", "               MAWWWWWWWWWWWWWAM               ", "               MANOONOONOONOONAM               ", "               MGGGGGGGGGGGGGGGM               ", "               MGGGGGGGGGGGGGGGM               ", "               MNNNNNNNNNNNNNNNM               ", "               MGGGGGGGGGGGGGGGM               ", "               MGGGGGGGGGGGGGGGM               ", "               M   O   O   O   M               ", "                                               ", "                                               ", "                                               ", "                                               ", "                                               ", "                                               ", "                                               ", "                                               ", "                                               ", "                                               ")
                .aisle("              LQQQQQQQQQQQQQQQQQL              ", "               MDNNNNNNNNNNNNNDM               ", "               MDTTTTTTTTTTTTTDM               ", "               MDNNNNNNNNNNNNNDM               ", "               MVVVVVVVVVVVVVVVM               ", "               ML             LM               ", "      D        L               L        D      ", "      D        L               L        D      ", "      D        L               L        D      ", "      D        MLLLLLLLLLLLLLLLM        D      ", "      D        MMMMMMMMMMMMMMMMM        D      ", "      D                                 D      ", "      D                                 D      ", "      D                                 D      ", "                                               ", "                                               ", "                                               ", "                                               ", "                                               ", "                                               ")
                .aisle("              LQQQQQQQQQQQQQQQQQL              ", "               MDXYYYYYYYYYYYXDM               ", "               MDTGGGGGGGGGGGTDM               ", "               MDXUUUUUUUUUUUXDM               ", "               ML             LM               ", "      D        LL             LL        D      ", "     MPMMMMMMMML               LMMMMMMMMPM     ", "     MPMCCCCCCCL               LCCCCCCCMPM     ", "     MPMMMMMMMML               LMMMMMMMMPM     ", "     MPM       LLLLNNNNNLLNNNNLL       MPM     ", "     MPM       MCCCCCCCCCCCCCCCM       MPM     ", "     MPM                               MPM     ", "     MPM                               MPM     ", "     MPM                               MPM     ", "      D                                 D      ", "                                               ", "                                               ", "                                               ", "                                               ", "                                               ")
                .aisle("              LQQQQQQQQQQQQQQQQQL              ", "              OMDT           TDMO              ", "              OMDTGGGGGGGGGGGTDMO              ", "              OMDTWWWWWWWWWWWTDMO              ", "      X       OMLT  W  W  W  TLMO       X      ", "     DPD      OLLT  W  W  W  TLLO      DPD     ", "    DPPPLLLLLLLL T  W  W  W  T LLLLLLLLPPPD    ", "    DPWWWWWWWWWWWWWWWWWWWWWWWWWWWWWWWWWWWPD    ", "    DPWPLLLLLLLL               LLLLLLLLPWPD    ", "    DPWPD      LNNNNLLLNNNNLLNNL      DPWPD    ", "    DPWPD      MCCCCCCCCCCCCCCCM      DPWPD    ", "    DPWPD                             DPWPD    ", "    DPWPD                             DPWPD    ", "    DPPPD                             DPPPD    ", "     DPD                               DPD     ", "      X                                 X      ", "                                               ", "                                               ", "                                               ", "                                               ")
                .aisle("              LQQQQQQQQQQQQQQQQQL              ", "               MDXYYYYYYYYYYYXDM               ", "               MDTGGGGGGGGGGGTDM               ", "               MDXUUUUUUUUUUUXDM               ", "               ML             LM               ", "      D        LL             LL        D      ", "     MPMMMMMMMML               LMMMMMMMMPM     ", "     MPMCCCCCCCL               LCCCCCCCMPM     ", "     MPMMMMMMMML               LMMMMMMMMPM     ", "     MPM       LLLLNNNNNLLNNNNLL       MPM     ", "     MPM       MCCCCCCCCCCCCCCCM       MPM     ", "     MPM                               MPM     ", "     LWL                               LWL     ", "     MPM                               MPM     ", "      D                                 D      ", "                                               ", "                                               ", "                                               ", "                                               ", "                                               ")
                .aisle("              LQQQQQQQQQQQQQQQQQL              ", "               MDNNNNNNNNNNNNNDM               ", "               MDTTTTTTTTTTTTTDM               ", "               MDNNNNNNNNNNNNNDM               ", "               MVVVVVVVVVVVVVVVM               ", "               ML             LM               ", "      D        L               L        D      ", "      D        L               L        D      ", "      D        L               L        D      ", "      D        MLLLLLLLLLLLLLLLM        D      ", "      D        MMMMMMMMMMMMMMMMM        D      ", "     MDM                               MDM     ", "     LWL                               LWL     ", "     MCM                               MCM     ", "                                               ", "                                               ", "                                               ", "                                               ", "                                               ", "                                               ")
                .aisle("              LQQQQQQQQQQQQQQQQQL              ", "               MANOONOONOONOONAM               ", "               MAWWWWWWWWWWWWWAM               ", "               MANOONOONOONOONAM               ", "               MGGGGGGGGGGGGGGGM               ", "               MGGGGGGGGGGGGGGGM               ", "               MNNNNNNNNNNNNNNNM               ", "               MGGGGGGGGGGGGGGGM               ", "               MGGGGGGGGGGGGGGGM               ", "               M   O   O   O   M               ", "                                               ", "     MCM                               MCM     ", "     LWL                               LWL     ", "     MCM                               MCM     ", "                                               ", "                                               ", "                                               ", "                                               ", "                                               ", "                                               ")
                .aisle("              LLQQQQQQQQQQQQQQQLL              ", "                ALLLLLLLLLLLLLA                ", "                ACCCCCCCCCCCCCA                ", "               MALLLLLLLLLLLLLAM               ", "                   O   O   O                   ", "                   O   O   O                   ", "                   O   O   O                   ", "                   O   O   O                   ", "                   O   O   O                   ", "                   O   O   O                   ", "                                               ", "     MCM                               MCM     ", "     LWL                               LWL     ", "     MCM                               MCM     ", "                                               ", "                                               ", "                                               ", "                                               ", "                                               ", "                                               ")
                .aisle("               LLLLLLLLLLLLLLLLL               ", "                   L   L   L                   ", "                   L   L   L                   ", "                MMMMMMMMMMMMMMM                ", "                                               ", "                                               ", "                                               ", "                                               ", "                                               ", "                                               ", "                                               ", "     MCM                               MCM     ", "     LWL                               LWL     ", "     MCM                               MCM     ", "                                               ", "                                               ", "                                               ", "                                               ", "                                               ", "                                               ")
                .aisle("                                               ", "                                               ", "                                               ", "                       @                       ", "                                               ", "                                               ", "                                               ", "                                               ", "                                               ", "                                               ", "                                               ", "     MCM                               MCM     ", "     LWL                               LWL     ", "     MCM                               MCM     ", "                                               ", "                                               ", "                                               ", "                                               ", "                                               ", "                                               ")
                .aisle("                                               ", "                                               ", "                                               ", "                                               ", "                                               ", "                                               ", "                                               ", "                                               ", "                                               ", "                                               ", "                                               ", "     MCM                               MCM     ", "     LWL                               LWL     ", "     MCM                               MCM     ", "                                               ", "                                               ", "                                               ", "                                               ", "                                               ", "                                               ")
                .aisle("                                               ", "                                               ", "                                               ", "                                               ", "                                               ", "                                               ", "                                               ", "                                               ", "                                               ", "                                               ", "                                               ", "     MCM                               MCM     ", "     LWL                               LWL     ", "     MCM                               MCM     ", "                                               ", "                                               ", "                                               ", "                                               ", "                                               ", "                                               ")
                .aisle("                                               ", "                                               ", "                                               ", "                                               ", "                                               ", "                                               ", "                                               ", "                                               ", "                                               ", "                                               ", "                                               ", "     MCM                               MCM     ", "     LWL                               LWL     ", "     MCM                               MCM     ", "                                               ", "                                               ", "                                               ", "                                               ", "                                               ", "                                               ")
                .aisle("    LLLLL                             LLLLL    ", "                                               ", "                                               ", "                                               ", "                                               ", "                                               ", "                                               ", "                                               ", "                                               ", "                                               ", "                                               ", "     MCM                               MCM     ", "     LWL                               LWL     ", "     MCM                               MCM     ", "                                               ", "                                               ", "                                               ", "                                               ", "                                               ", "                                               ")
                .aisle("  LLLUUULLL                         LLLUUULLL  ", "    MMMMM                             MMMMM    ", "                                               ", "                                               ", "                                               ", "                                               ", "                                               ", "                                               ", "    MMMMM                             MMMMM    ", "                                               ", "                                               ", "     MCM                               MCM     ", "     LWL                               LWL     ", "     MCM                               MCM     ", "                                               ", "                                               ", "   LLLLLLL                           LLLLLLL   ", "      L                                 L      ", "                                               ", "                                               ")
                .aisle(" LLUUUUUUULL                       LLUUUUUUULL ", "   MALLLAM                           MALLLAM   ", "    ACCCA                             ACCCA    ", "    ACCCA                             ACCCA    ", "    ACCCA                             ACCCA    ", "    ACCCA                             ACCCA    ", "    ACCCA                             ACCCA    ", "    ACCCA                             ACCCA    ", "   MMLLLMM                           MMLLLMM   ", "    MAAAM                             MAAAM    ", "    MACAM                             MACAM    ", "    MACAM                             MACAM    ", "    MAWAM                             MACAM    ", "    MACAM                             MACAM    ", "    MACAM                             MACAM    ", "    MAAAM                             MAAAM    ", "  L MFFFM L                         L MFFFM L  ", "   MMMMMMM                           MMMMMMM   ", "      L                                 L      ", "                                               ")
                .aisle(" LUUUUUUUUUL                       LUUUUUUUUUL ", "  MGOOOOOGM                         MGOOOOOGM  ", "   GOVVVOG                           GOVVVOG   ", "   GO   OG                           GO   OG   ", "   GOVVVOG                           GOVVVOG   ", "   GO   OG                           GO   OG   ", "   GOVVVOG                           GOVVVOG   ", "   GO   OG                           GO   OG   ", "  MMUUUUUMM                         MMUUUUUMM  ", "   G     G                           G     G   ", "   GO W OG                           GO W OG   ", "   G  W  G                           G  W  G   ", "   GWWWWWG                           GWWWWWG   ", "   G  W  G                           G  W  G   ", "   GO W OG                           GO W OG   ", "   G     G                           G     G   ", " L GUUUUUG L                       L GUUUUUG L ", "  MMMMMMMMM                         MMMMMMMMM  ", "      L                                 L      ", "                                               ")
                .aisle("LLUUUUUUUUULL                     LLUUUUUUUUULL", " MAOOVVVOOAM                       MAOOVVVOOAM ", "  AOV   VOA                         AOV   VOA  ", "  AO VVV OA                         AO VVV OA  ", "  AOV   VOA                         AOV   VOA  ", "  AO VVV OA                         AO VVV OA  ", "  AOV   VOA                         AOV   VOA  ", "  AO VVV OA                         AO VVV OA  ", " MMUUUUUUUMM                       MMUUUUUUUMM ", "  M O W O M                         M O W O M  ", "  MOX   XOM                         MOX   XOM  ", "  M       M                         M       M  ", "  MW     WM                         MW     WM  ", "  M       M                         M       M  ", "  MOX   XOM                         MOX   XOM  ", "  M O W O M                         M O W O M  ", " LMUUUUUUUML                       LMUUUUUUUML ", "  MMOMMMOMM                         MMOMMMOMM  ", "    O L O                             O L O    ", "    OOOOO                             OOOOO    ")
                .aisle("LUUUUUUUUUUUL                     LUUUUUUUUUUUL", " MLOVVXVVOLM                       MLOVVXVVOLM ", "  CV  V  VC                         CV  V  VC  ", "  C VVXVV C                         C VVXVV C  ", "  CV  V  VC                         CV  V  VC  ", "  C VVXVV C                         C VVXVV C  ", "  CV  V  VC                         CV  V  VC  ", "  C VVXVV C                         C VVXVV C  ", " MLUUUUUUULM                       MLUUUUUUULM ", "  A   W   A                         A   W   A  ", "  A       A                         A       A  ", "  A       A                         A       A  ", "  AW     WA                         AW     WA  ", "  A       A                         A       A  ", "  A       A                         A       A  ", "  A   W   A                         A   W   A  ", " LFUUUUUUUFL                       LFUUUUUUUFL ", "  MMMMMMMMM                         MMMMMMMMM  ", "      L                                 L      ", "    O   O                             O   O    ")
                .aisle("LUUUUUUUUUUUL                     LUUUUUUUUUUUL", " MLOVXTXVOLM                       MLOVXTXVOLM ", "  CV VTV VC                         CV VTV VC  ", "  C VXTXV C                         C VXTXV C  ", "  CV VTV VC                         CV VTV VC  ", "  C VXTXV C                         C VXTXV C  ", "  CV VTV VC                         CV VTV VC  ", "  C VXTXV C                         C VXTXV C  ", " MLUUUTUUULM                       MLUUUTUUULM ", "  A WWTWW A                         A WWTWW A  ", "  CW     WC                         CW     WC  ", "  CW     WC                         CW     WC  ", "  CW     WC                         CW     WC  ", "  CW     WC                         CW     WC  ", "  CW     WC                         CW     WC  ", "  A WWWWW A                         A WWWWW A  ", " LFUUUUUUUFL                       LFUUUUUUUFL ", " LMMMMMMMMML                       LMMMMMMMMML ", "  LLLLLLLLL                         LLLLLLLLL  ", "    O   O                             O   O    ")
                .aisle("LUUUUUUUUUUUL                     LUUUUUUUUUUUL", " MLOVVXVVOLM                       MLOVVXVVOLM ", "  CV  V  VC                         CV  V  VC  ", "  C VVXVV C                         C VVXVV C  ", "  CV  V  VC                         CV  V  VC  ", "  C VVXVV C                         C VVXVV C  ", "  CV  V  VC                         CV  V  VC  ", "  C VVXVV C                         C VVXVV C  ", " MLUUUUUUULM                       MLUUUUUUULM ", "  A   W   A                         A   W   A  ", "  A       A                         A       A  ", "  A       A                         A       A  ", "  AW     WA                         AW     WA  ", "  A       A                         A       A  ", "  A       A                         A       A  ", "  A   W   A                         A   W   A  ", " LFUUUUUUUFL                       LFUUUUUUUFL ", "  MMMMMMMMM                         MMMMMMMMM  ", "      L                                 L      ", "    O   O                             O   O    ")
                .aisle("LLUUUUUUUUULL                     LLUUUUUUUUULL", " MAOOVVVOOAM                       MAOOVVVOOAM ", "  AOV   VOA                         AOV   VOA  ", "  AO VVV OA                         AO VVV OA  ", "  AOV   VOA                         AOV   VOA  ", "  AO VVV OA                         AO VVV OA  ", "  AOV   VOA                         AOV   VOA  ", "  AO VVV OA                         AO VVV OA  ", " MMUUUUUUUMM                       MMUUUUUUUMM ", "  M O W O M                         M O W O M  ", "  MOX   XOM                         MOX   XOM  ", "  M       M                         M       M  ", "  MW     WM                         MW     WM  ", "  M       M                         M       M  ", "  MOX   XOM                         MOX   XOM  ", "  M O W O M                         M O W O M  ", " LMUUUUUUUML                       LMUUUUUUUML ", "  MMOMMMOMM                         MMOMMMOMM  ", "    O L O                             O L O    ", "    OOOOO                             OOOOO    ")
                .aisle(" LUUUUUUUUUL                       LUUUUUUUUUL ", "  MGOOOOOGM                         MGOOOOOGM  ", "   GOVVVOG                           GOVVVOG   ", "   GO   OG                           GO   OG   ", "   GOVVVOG                           GOVVVOG   ", "   GO   OG                           GO   OG   ", "   GOVVVOG                           GOVVVOG   ", "   GO   OG                           GO   OG   ", "  MMUUUUUMM                         MMUUUUUMM  ", "   G     G                           G     G   ", "   GO W OG                           GO W OG   ", "   G  W  G                           G  W  G   ", "   GWWWWWG                           GWWWWWG   ", "   G  W  G                           G  W  G   ", "   GO W OG                           GO W OG   ", "   G     G                           G     G   ", " L GUUUUUG L                       L GUUUUUG L ", "  MMMMMMMMM                         MMMMMMMMM  ", "      L                                 L      ", "                                               ")
                .aisle(" LLUUUUUUULL                       LLUUUUUUULL ", "   MALLLAM                           MALLLAM   ", "    ACCCA                             ACCCA    ", "    ACCCA                             ACCCA    ", "    ACCCA                             ACCCA    ", "    ACCCA                             ACCCA    ", "    ACCCA                             ACCCA    ", "    ACCCA                             ACCCA    ", "   MMLLLMM                           MMLLLMM   ", "    MAAAM                             MAAAM    ", "    MACAM                             MACAM    ", "    MACAM                             MACAM    ", "    MACAM                             MACAM    ", "    MACAM                             MACAM    ", "    MACAM                             MACAM    ", "    MAAAM                             MAAAM    ", "  L MFFFM L                         L MFFFM L  ", "   MMMMMMM                           MMMMMMM   ", "      L                                 L      ", "                                               ")
                .aisle("  LLLUUULLL                         LLLUUULLL  ", "    MMMMM                             MMMMM    ", "                                               ", "                                               ", "                                               ", "                                               ", "                                               ", "                                               ", "    MMMMM                             MMMMM    ", "                                               ", "                                               ", "                                               ", "                                               ", "                                               ", "                                               ", "                                               ", "   LLLLLLL                           LLLLLLL   ", "      L                                 L      ", "                                               ", "                                               ")
                .aisle("    LLLLL                             LLLLL    ", "                                               ", "                                               ", "                                               ", "                                               ", "                                               ", "                                               ", "                                               ", "                                               ", "                                               ", "                                               ", "                                               ", "                                               ", "                                               ", "                                               ", "                                               ", "                                               ", "                                               ", "                                               ", "                                               ")
                .port('@', StructureModuleKeys.MODULE_IN, RelativeDirection.FRONT)
                .build();
    }

    @Nullable
    @Override
    public GTRecipe getRealRecipe(RecipeHandlerUnit unit, GTRecipe recipe) {
        int tier = getEffectiveTier();
        if (tier < 2) {
            if (recipe.getInputEUt() > 30719) {
                IdleReason.BLOCK_TIER_NOT_SATISFIES.setReason(this, recipe.getInputEUt() > 491519 ? 3 : 2, tier);
                return null;
            }
        } else if (tier < 3) {
            if (recipe.getInputEUt() > 491519) {
                IdleReason.BLOCK_TIER_NOT_SATISFIES.setReason(this, 3, tier);
                return null;
            }
        }
        recipe = GTORecipeModifiers.parallel(this, unit, recipe);
        if (recipe == null) return null;
        return super.getRealRecipe(unit, recipe);
    }

    @Override
    public void customText(List<Component> textList) {
        super.customText(textList);
        if (MultiblockPage.isScreenText()) return;
        textList.add(Component.translatable(STRUCTURE_TIER, structureTier));
        textList.add(Component.translatable(SWARM_TIER, machineTier));
        textList.add(Component.translatable(EFFECTIVE_TIER, getEffectiveTier()));
    }

    @Override
    public void addScreenReadouts(MultiblockPage page) {
        super.addScreenReadouts(page);
        page.addReading(STRUCTURE_TIER, MultiblockPage.numberText(() -> structureTier, ""));
        page.addReading(SWARM_TIER, MultiblockPage.numberText(() -> machineTier, ""));
        page.addNumber(EFFECTIVE_TIER_NAME, this::getEffectiveTier, "").tooltips(EFFECTIVE_TIER_DESC);
    }

    @Override
    public String getStorageSlotLabel() {
        return IStorageMultiblock.SLOT_NANITES;
    }
}
